using System;
using System.Collections.Generic;
using System.Linq;
using System.Threading;
using System.Threading.Tasks;
using FluentAssertions;
using MediatR;
using Moq;
using Xunit;
using FluentValidation;
using FluentValidation.Results;
using MyProject.Application.Common.Behaviours; // Ensure this matches the actual namespace of the ValidationBehavior

namespace MyProject.Tests
{
    public class ValidationBehaviorTests
    {
        private readonly Mock<IEnumerable<IValidator<TRequest>>> _mockValidators;
        private readonly Mock<RequestHandlerDelegate<TResponse>> _mockNext;
        private readonly ValidationBehavior<TRequest, TResponse> _behavior;

        public ValidationBehaviorTests()
        {
            _mockValidators = new Mock<IEnumerable<IValidator<TRequest>>>();
            _mockNext = new Mock<RequestHandlerDelegate<TResponse>>();
            _behavior = new ValidationBehavior<TRequest, TResponse>(_mockValidators.Object);
        }

        #region Critical Path Tests
        // Tests that protect core revenue-generating business processes
        // REQUIRED for: payments, user data, file uploads, core workflows

        [Fact]
        [Trait("Category", "Critical")]
        public async Task Handle_WithValidRequest_DoesNotThrowValidationException()
        {
            // Business Context: Successful validation should not throw an exception
            // Arrange
            var request = new TRequest();
            _mockValidators.Setup(v => v.GetEnumerator()).Returns(Enumerable.Empty<IValidator<TRequest>>().GetEnumerator());

            // Act & Assert
            await _behavior.Invoking(b => b.Handle(request, _mockNext.Object, CancellationToken.None))
                .Should().NotThrowAsync<ValidationException>();
        }

        [Fact]
        [Trait("Category", "Critical")]
        public async Task Handle_WithInvalidRequest_ThrowsValidationException()
        {
            // Business Context: Invalid validation should throw a ValidationException
            // Arrange
            var request = new TRequest();
            var mockValidator = new Mock<IValidator<TRequest>>();
            var validationFailure = new ValidationFailure("PropertyName", "Error message");
            var validationResult = new ValidationResult(new List<ValidationFailure> { validationFailure });

            mockValidator.Setup(v => v.ValidateAsync(It.IsAny<ValidationContext<TRequest>>(), It.IsAny<CancellationToken>()))
                .ReturnsAsync(validationResult);
            _mockValidators.Setup(v => v.GetEnumerator()).Returns(new List<IValidator<TRequest>> { mockValidator.Object }.GetEnumerator());

            // Act & Assert
            await _behavior.Invoking(b => b.Handle(request, _mockNext.Object, CancellationToken.None))
                .Should().ThrowAsync<ValidationException>()
                .WithMessage("*Error message*");
        }

        #endregion

        #region Happy Path Tests
        // Standard expected workflows under normal conditions

        [Fact]
        [Trait("Category", "HappyPath")]
        public async Task Handle_WithNoValidators_DoesNotThrowValidationException()
        {
            // Business Context: No validators should not throw an exception
            // Arrange
            var request = new TRequest();
            _mockValidators.Setup(v => v.GetEnumerator()).Returns(Enumerable.Empty<IValidator<TRequest>>().GetEnumerator());

            // Act & Assert
            await _behavior.Invoking(b => b.Handle(request, _mockNext.Object, CancellationToken.None))
                .Should().NotThrowAsync<ValidationException>();
        }

        #endregion

        #region Edge Case Tests
        // Boundary conditions and unusual but valid scenarios

        [Fact]
        [Trait("Category", "EdgeCase")]
        public async Task Handle_WithMultipleValidators_AllValidatorsAreCalled()
        {
            // Business Context: Multiple validators should all be called
            // Arrange
            var request = new TRequest();
            var mockValidator1 = new Mock<IValidator<TRequest>>();
            var mockValidator2 = new Mock<IValidator<TRequest>>();

            mockValidator1.Setup(v => v.ValidateAsync(It.IsAny<ValidationContext<TRequest>>(), It.IsAny<CancellationToken>()))
                .ReturnsAsync(new ValidationResult());
            mockValidator2.Setup(v => v.ValidateAsync(It.IsAny<ValidationContext<TRequest>>(), It.IsAny<CancellationToken>()))
                .ReturnsAsync(new ValidationResult());

            _mockValidators.Setup(v => v.GetEnumerator()).Returns(new List<IValidator<TRequest>> { mockValidator1.Object, mockValidator2.Object }.GetEnumerator());

            // Act
            await _behavior.Handle(request, _mockNext.Object, CancellationToken.None);

            // Assert
            mockValidator1.Verify(v => v.ValidateAsync(It.IsAny<ValidationContext<TRequest>>(), It.IsAny<CancellationToken>()), Times.Once);
            mockValidator2.Verify(v => v.ValidateAsync(It.IsAny<ValidationContext<TRequest>>(), It.IsAny<CancellationToken>()), Times.Once);
        }

        #endregion

        #region Negative Tests
        // Invalid inputs and expected failure scenarios

        [Fact]
        [Trait("Category", "Negative")]
        public async Task Handle_WithNullRequest_ThrowsArgumentNullException()
        {
            // Business Context: Null request should throw an ArgumentNullException
            // Arrange
            TRequest? request = null;

            // Act & Assert
            await _behavior.Invoking(b => b.Handle(request!, _mockNext.Object, CancellationToken.None))
                .Should().ThrowAsync<ArgumentNullException>()
                .WithMessage("*request*");
        }

        #endregion

        #region Exception Handling Tests
        // System resilience and graceful degradation

        [Fact]
        [Trait("Category", "ExceptionHandling")]
        public async Task Handle_WithValidatorThrowingException_ThrowsValidationException()
        {
            // Business Context: Validator throwing an exception should be caught and rethrown as ValidationException
            // Arrange
            var request = new TRequest();
            var mockValidator = new Mock<IValidator<TRequest>>();
            mockValidator.Setup(v => v.ValidateAsync(It.IsAny<ValidationContext<TRequest>>(), It.IsAny<CancellationToken>()))
                .ThrowsAsync(new Exception("Validator error"));

            _mockValidators.Setup(v => v.GetEnumerator()).Returns(new List<IValidator<TRequest>> { mockValidator.Object }.GetEnumerator());

            // Act & Assert
            await _behavior.Invoking(b => b.Handle(request, _mockNext.Object, CancellationToken.None))
                .Should().ThrowAsync<ValidationException>()
                .WithMessage("*Validator error*");
        }

        #endregion
    }

    // Dummy classes to compile the test
    public class TRequest { }
    public class TResponse { }
}